<?xml version="1.0" encoding="utf-8"?>
<!-- This URDF was automatically created by SolidWorks to URDF Exporter! Originally created by Stephen Brawner (brawner@gmail.com) 
     Commit Version: 1.6.0-1-g15f4949  Build Version: 1.6.7594.29634
     For more information, please see http://wiki.ros.org/sw_urdf_exporter -->
<robot
  name="mini_4wd_arm">
  <link
    name="base_link">
    <inertial>
      <origin
        xyz="-0.022642 0.0015027 0.12689"
        rpy="0 0 0" />
      <mass
        value="0.89799" />
      <inertia
        ixx="0.0013044"
        ixy="8.7142E-07"
        ixz="4.5432E-07"
        iyy="0.0013098"
        iyz="1.065E-07"
        izz="0.001728" />
    </inertial>
    <visual>
      <origin
        xyz="0 0 0"
        rpy="0 0 0" />
      <geometry>
        <mesh
          filename="package://mini_4wd_arm/meshes/base_link.STL" />
      </geometry>
      <material
        name="">
        <color
          rgba="1 1 1 1" />
      </material>
    </visual>
    <collision>
      <origin
        xyz="0 0 0"
        rpy="0 0 0" />
      <geometry>
        <mesh
          filename="package://mini_4wd_arm/meshes/base_link.STL" />
      </geometry>
    </collision>
  </link>
  <link
    name="right_rear_wheel_link">
    <inertial>
      <origin
        xyz="6.83202003928796E-08 -0.00981114988984491 -7.06755701219974E-07"
        rpy="0 0 0" />
      <mass
        value="0.0537742719170435" />
      <inertia
        ixx="1.99604444246395E-05"
        ixy="4.1596031792141E-15"
        ixz="1.15441018518572E-14"
        iyy="3.41112993518182E-05"
        iyz="-1.43003760924822E-14"
        izz="1.99600030132708E-05" />
    </inertial>
    <visual>
      <origin
        xyz="0 0 0"
        rpy="0 0 0" />
      <geometry>
        <mesh
          filename="package://mini_4wd_arm/meshes/right_rear_wheel_link.STL" />
      </geometry>
      <material
        name="">
        <color
          rgba="0.741176470588235 0.901960784313726 0.956862745098039 1" />
      </material>
    </visual>
    <collision>
      <origin
        xyz="0 0 0"
        rpy="0 0 0" />
      <geometry>
        <mesh
          filename="package://mini_4wd_arm/meshes/right_rear_wheel_link.STL" />
      </geometry>
    </collision>
  </link>
  <joint
    name="right_rear_wheel_joint"
    type="continuous">
    <origin
      xyz="-0.1005 -0.08661 0.032001"
      rpy="0 0 0" />
    <parent
      link="base_link" />
    <child
      link="right_rear_wheel_link" />
    <axis
      xyz="0 1 0" />
  </joint>
  <link
    name="right_front_wheel_link">
    <inertial>
      <origin
        xyz="6.83202033835428E-08 -0.00981114988984488 -7.06755701219974E-07"
        rpy="0 0 0" />
      <mass
        value="0.0537742719170435" />
      <inertia
        ixx="1.99604444246395E-05"
        ixy="4.15960366377729E-15"
        ixz="1.15441045153765E-14"
        iyy="3.41112993518181E-05"
        iyz="-1.43003767219854E-14"
        izz="1.99600030132707E-05" />
    </inertial>
    <visual>
      <origin
        xyz="0 0 0"
        rpy="0 0 0" />
      <geometry>
        <mesh
          filename="package://mini_4wd_arm/meshes/right_front_wheel_link.STL" />
      </geometry>
      <material
        name="">
        <color
          rgba="0.741176470588235 0.901960784313726 0.956862745098039 1" />
      </material>
    </visual>
    <collision>
      <origin
        xyz="0 0 0"
        rpy="0 0 0" />
      <geometry>
        <mesh
          filename="package://mini_4wd_arm/meshes/right_front_wheel_link.STL" />
      </geometry>
    </collision>
  </link>
  <joint
    name="right_front_wheel_joint"
    type="continuous">
    <origin
      xyz="0.0725 -0.08661 0.032001"
      rpy="0 0 0" />
    <parent
      link="base_link" />
    <child
      link="right_front_wheel_link" />
    <axis
      xyz="0 1 0" />
  </joint>
  <link
    name="left_rear_wheel_link">
    <inertial>
      <origin
        xyz="-6.83285442254489E-08 0.00981114988984495 -7.0683856357584E-07"
        rpy="0 0 0" />
      <mass
        value="0.0537742719170435" />
      <inertia
        ixx="1.99604444246395E-05"
        ixy="-4.15960250432221E-15"
        ixz="-1.1544101608417E-14"
        iyy="3.41112993518182E-05"
        iyz="-1.43003766057192E-14"
        izz="1.99600030132708E-05" />
    </inertial>
    <visual>
      <origin
        xyz="0 0 0"
        rpy="0 0 0" />
      <geometry>
        <mesh
          filename="package://mini_4wd_arm/meshes/left_rear_wheel_link.STL" />
      </geometry>
      <material
        name="">
        <color
          rgba="0.741176470588235 0.901960784313726 0.956862745098039 1" />
      </material>
    </visual>
    <collision>
      <origin
        xyz="0 0 0"
        rpy="0 0 0" />
      <geometry>
        <mesh
          filename="package://mini_4wd_arm/meshes/left_rear_wheel_link.STL" />
      </geometry>
    </collision>
  </link>
  <joint
    name="left_rear_wheel_joint"
    type="continuous">
    <origin
      xyz="-0.1005 0.08939 0.032001"
      rpy="0 0 0" />
    <parent
      link="base_link" />
    <child
      link="left_rear_wheel_link" />
    <axis
      xyz="0 1 0" />
  </joint>
  <link
    name="left_front_wheel_link">
    <inertial>
      <origin
        xyz="-6.83285412694801E-08 0.00981114988984495 -7.06838563666046E-07"
        rpy="0 0 0" />
      <mass
        value="0.0537742719170435" />
      <inertia
        ixx="1.99604444246395E-05"
        ixy="-4.15960236341372E-15"
        ixz="-1.15441039766573E-14"
        iyy="3.41112993518181E-05"
        iyz="-1.43003769092411E-14"
        izz="1.99600030132707E-05" />
    </inertial>
    <visual>
      <origin
        xyz="0 0 0"
        rpy="0 0 0" />
      <geometry>
        <mesh
          filename="package://mini_4wd_arm/meshes/left_front_wheel_link.STL" />
      </geometry>
      <material
        name="">
        <color
          rgba="0.741176470588235 0.901960784313726 0.956862745098039 1" />
      </material>
    </visual>
    <collision>
      <origin
        xyz="0 0 0"
        rpy="0 0 0" />
      <geometry>
        <mesh
          filename="package://mini_4wd_arm/meshes/left_front_wheel_link.STL" />
      </geometry>
    </collision>
  </link>
  <joint
    name="left_front_wheel_joint"
    type="continuous">
    <origin
      xyz="0.0725 0.08939 0.032001"
      rpy="0 0 0" />
    <parent
      link="base_link" />
    <child
      link="left_front_wheel_link" />
    <axis
      xyz="0 1 0" />
  </joint>
  <link
    name="link1">
    <inertial>
      <origin
        xyz="-0.0100000001129828 0.00272644506965478 0.0525"
        rpy="0 0 0" />
      <mass
        value="0.0182961255655804" />
      <inertia
        ixx="1.62397575138128E-05"
        ixy="3.59330528692255E-13"
        ixz="4.5193508144873E-21"
        iyy="7.56857037469918E-06"
        iyz="6.02550756458972E-20"
        izz="1.05132687532751E-05" />
    </inertial>
    <visual>
      <origin
        xyz="0 0 0"
        rpy="0 0 0" />
      <geometry>
        <mesh
          filename="package://mini_4wd_arm/meshes/link1.STL" />
      </geometry>
      <material
        name="">
        <color
          rgba="0.741176470588235 0.901960784313726 0.956862745098039 1" />
      </material>
    </visual>
    <collision>
      <origin
        xyz="0 0 0"
        rpy="0 0 0" />
      <geometry>
        <mesh
          filename="package://mini_4wd_arm/meshes/link1.STL" />
      </geometry>
    </collision>
  </link>
  <joint
    name="joint1"
    type="revolute">
    <origin
      xyz="0.095 0.0098391 0.1525"
      rpy="0 0 0" />
    <parent
      link="base_link" />
    <child
      link="link1" />
    <axis
      xyz="0 1 0" />
    <limit
      lower="-1.57"
      upper="1.57"
      effort="0"
      velocity="0" />
  </joint>
  <link
    name="link2">
    <inertial>
      <origin
        xyz="-0.00116494658594929 -0.00200902341959693 0.0106973068371073"
        rpy="0 0 0" />
      <mass
        value="0.04881953625606" />
      <inertia
        ixx="1.97462867733434E-05"
        ixy="1.45082117414484E-07"
        ixz="-1.29484666846208E-07"
        iyy="1.15881140697428E-05"
        iyz="1.52071956525967E-07"
        izz="1.21275429251273E-05" />
    </inertial>
    <visual>
      <origin
        xyz="0 0 0"
        rpy="0 0 0" />
      <geometry>
        <mesh
          filename="package://mini_4wd_arm/meshes/link2.STL" />
      </geometry>
      <material
        name="">
        <color
          rgba="0.741176470588235 0.901960784313726 0.956862745098039 1" />
      </material>
    </visual>
    <collision>
      <origin
        xyz="0 0 0"
        rpy="0 0 0" />
      <geometry>
        <mesh
          filename="package://mini_4wd_arm/meshes/link2.STL" />
      </geometry>
    </collision>
  </link>
  <joint
    name="joint2"
    type="revolute">
    <origin
      xyz="-0.01 0.002 0.115"
      rpy="0 0 0" />
    <parent
      link="link1" />
    <child
      link="link2" />
    <axis
      xyz="0 -1 0" />
    <limit
      lower="-1.57"
      upper="1.57"
      effort="0"
      velocity="0" />
  </joint>
  <link
    name="link3">
    <inertial>
      <origin
        xyz="0.00944842236281482 -0.00534874562465814 0.0219925759504686"
        rpy="0 0 0" />
      <mass
        value="0.0774400381605552" />
      <inertia
        ixx="1.8806021749288E-05"
        ixy="1.43436871650939E-07"
        ixz="-7.16494718648727E-11"
        iyy="1.29730531033493E-05"
        iyz="1.41803265068013E-07"
        izz="1.69048155841586E-05" />
    </inertial>
    <visual>
      <origin
        xyz="0 0 0"
        rpy="0 0 0" />
      <geometry>
        <mesh
          filename="package://mini_4wd_arm/meshes/link3.STL" />
      </geometry>
      <material
        name="">
        <color
          rgba="0.741176470588235 0.901960784313726 0.956862745098039 1" />
      </material>
    </visual>
    <collision>
      <origin
        xyz="0 0 0"
        rpy="0 0 0" />
      <geometry>
        <mesh
          filename="package://mini_4wd_arm/meshes/link3.STL" />
      </geometry>
    </collision>
  </link>
  <joint
    name="joint3"
    type="revolute">
    <origin
      xyz="0.001 0.0005 0.0975"
      rpy="0 0 0" />
    <parent
      link="link2" />
    <child
      link="link3" />
    <axis
      xyz="0 1 0" />
    <limit
      lower="-1.57"
      upper="1.57"
      effort="0"
      velocity="0" />
  </joint>
  <link
    name="link4">
    <inertial>
      <origin
        xyz="-0.000764929259273711 -0.00369362333606303 0.00436132757394275"
        rpy="0 0 0" />
      <mass
        value="0.00297108566800572" />
      <inertia
        ixx="4.07485385419207E-07"
        ixy="8.35911875920514E-15"
        ixz="-5.83787734243774E-15"
        iyy="2.05767246894319E-07"
        iyz="1.40876829989051E-07"
        izz="2.13065038138537E-07" />
    </inertial>
    <visual>
      <origin
        xyz="0 0 0"
        rpy="0 0 0" />
      <geometry>
        <mesh
          filename="package://mini_4wd_arm/meshes/link4.STL" />
      </geometry>
      <material
        name="">
        <color
          rgba="0.741176470588235 0.901960784313726 0.956862745098039 1" />
      </material>
    </visual>
    <collision>
      <origin
        xyz="0 0 0"
        rpy="0 0 0" />
      <geometry>
        <mesh
          filename="package://mini_4wd_arm/meshes/link4.STL" />
      </geometry>
    </collision>
  </link>
  <joint
    name="joint4"
    type="revolute">
    <origin
      xyz="-0.0035 -0.018767 0.044"
      rpy="0 0 0" />
    <parent
      link="link3" />
    <child
      link="link4" />
    <axis
      xyz="1 0 0" />
    <limit
      lower="-0.8"
      upper="0.8"
      effort="0"
      velocity="0" />
  </joint>
  <link
    name="link5">
    <inertial>
      <origin
        xyz="-0.014706899275805 -0.00503889804285509 0.00905348471357043"
        rpy="0 0 0" />
      <mass
        value="0.0110555779175678" />
      <inertia
        ixx="2.52333571336248E-06"
        ixy="-2.92815821512361E-14"
        ixz="-3.31260479852369E-13"
        iyy="2.26626917887801E-06"
        iyz="-3.12207718593082E-07"
        izz="7.09279722839571E-07" />
    </inertial>
    <visual>
      <origin
        xyz="0 0 0"
        rpy="0 0 0" />
      <geometry>
        <mesh
          filename="package://mini_4wd_arm/meshes/link5.STL" />
      </geometry>
      <material
        name="">
        <color
          rgba="0.741176470588235 0.901960784313726 0.956862745098039 1" />
      </material>
    </visual>
    <collision>
      <origin
        xyz="0 0 0"
        rpy="0 0 0" />
      <geometry>
        <mesh
          filename="package://mini_4wd_arm/meshes/link5.STL" />
      </geometry>
    </collision>
  </link>
  <joint
    name="joint5"
    type="revolute">
    <origin
      xyz="0.012641 -0.025609 0.03576"
      rpy="0 0 0" />
    <parent
      link="link4" />
    <child
      link="link5" />
    <axis
      xyz="1 0 0" />
    <limit
      lower="-0.8"
      upper="0.8"
      effort="0"
      velocity="0" />
  </joint>
  <link
    name="link6">
    <inertial>
      <origin
        xyz="-0.00450000023402264 0.00564731539871221 0.00640801185701556"
        rpy="0 0 0" />
      <mass
        value="0.00197604548440531" />
      <inertia
        ixx="3.99845023290322E-07"
        ixy="8.47344538742339E-15"
        ixz="6.28828615432781E-15"
        iyy="1.95368168459778E-07"
        iyz="-1.51745831304801E-07"
        izz="2.07440923057153E-07" />
    </inertial>
    <visual>
      <origin
        xyz="0 0 0"
        rpy="0 0 0" />
      <geometry>
        <mesh
          filename="package://mini_4wd_arm/meshes/link6.STL" />
      </geometry>
      <material
        name="">
        <color
          rgba="0.741176470588235 0.901960784313726 0.956862745098039 1" />
      </material>
    </visual>
    <collision>
      <origin
        xyz="0 0 0"
        rpy="0 0 0" />
      <geometry>
        <mesh
          filename="package://mini_4wd_arm/meshes/link6.STL" />
      </geometry>
    </collision>
  </link>
  <joint
    name="joint6"
    type="revolute">
    <origin
      xyz="-0.0005 0.0062333 0.044"
      rpy="0 0 0" />
    <parent
      link="link3" />
    <child
      link="link6" />
    <axis
      xyz="1 0 0" />
    <limit
      lower="-0.8"
      upper="0.8"
      effort="0"
      velocity="0" />
  </joint>
  <link
    name="link7">
    <inertial>
      <origin
        xyz="-0.0146836443735531 0.00463949405759529 0.00890032319474121"
        rpy="0 0 0" />
      <mass
        value="0.0110869919561474" />
      <inertia
        ixx="2.5235601193764E-06"
        ixy="7.39297511938173E-14"
        ixz="-4.60016212791094E-13"
        iyy="2.26639574215184E-06"
        iyz="3.12169913809393E-07"
        izz="7.09382731891093E-07" />
    </inertial>
    <visual>
      <origin
        xyz="0 0 0"
        rpy="0 0 0" />
      <geometry>
        <mesh
          filename="package://mini_4wd_arm/meshes/link7.STL" />
      </geometry>
      <material
        name="">
        <color
          rgba="0.741176470588235 0.901960784313726 0.956862745098039 1" />
      </material>
    </visual>
    <collision>
      <origin
        xyz="0 0 0"
        rpy="0 0 0" />
      <geometry>
        <mesh
          filename="package://mini_4wd_arm/meshes/link7.STL" />
      </geometry>
    </collision>
  </link>
  <joint
    name="joint7"
    type="revolute">
    <origin
      xyz="0.0096405 0.025982 0.035401"
      rpy="0 0 0" />
    <parent
      link="link6" />
    <child
      link="link7" />
    <axis
      xyz="1 0 0" />
    <limit
      lower="-0.8"
      upper="0.8"
      effort="0"
      velocity="0" />
  </joint>
  <link
    name="link8">
    <inertial>
      <origin
        xyz="-0.00400000053666988 0.0129506493361989 0.0118123207260397"
        rpy="0 0 0" />
      <mass
        value="0.00108778506953505" />
      <inertia
        ixx="1.71922619588063E-07"
        ixy="3.45167333148965E-15"
        ixz="3.43958151000498E-15"
        iyy="8.86285716063845E-08"
        iyz="-8.30022521497665E-08"
        izz="8.49257255859816E-08" />
    </inertial>
    <visual>
      <origin
        xyz="0 0 0"
        rpy="0 0 0" />
      <geometry>
        <mesh
          filename="package://mini_4wd_arm/meshes/link8.STL" />
      </geometry>
      <material
        name="">
        <color
          rgba="0.741176470588235 0.901960784313726 0.956862745098039 1" />
      </material>
    </visual>
    <collision>
      <origin
        xyz="0 0 0"
        rpy="0 0 0" />
      <geometry>
        <mesh
          filename="package://mini_4wd_arm/meshes/link8.STL" />
      </geometry>
    </collision>
  </link>
  <joint
    name="joint8"
    type="revolute">
    <origin
      xyz="0.0045 0.026437 0.036647"
      rpy="0 0 0" />
    <parent
      link="link3" />
    <child
      link="link8" />
    <axis
      xyz="-1 0 0" />
    <limit
      lower="-0.8"
      upper="0.8"
      effort="0"
      velocity="0" />
  </joint>
  <link
    name="link9">
    <inertial>
      <origin
        xyz="-0.00699999947061911 -0.0127747673207715 0.0120023151330466"
        rpy="0 0 0" />
      <mass
        value="0.00108778506953502" />
      <inertia
        ixx="1.71922619588055E-07"
        ixy="3.35010939121811E-15"
        ixz="-3.43581214196693E-15"
        iyy="9.10794072428557E-08"
        iyz="8.29113514522138E-08"
        izz="8.24748899495017E-08" />
    </inertial>
    <visual>
      <origin
        xyz="0 0 0"
        rpy="0 0 0" />
      <geometry>
        <mesh
          filename="package://mini_4wd_arm/meshes/link9.STL" />
      </geometry>
      <material
        name="">
        <color
          rgba="0.741176470588235 0.901960784313726 0.956862745098039 1" />
      </material>
    </visual>
    <collision>
      <origin
        xyz="0 0 0"
        rpy="0 0 0" />
      <geometry>
        <mesh
          filename="package://mini_4wd_arm/meshes/link9.STL" />
      </geometry>
    </collision>
  </link>
  <joint
    name="joint9"
    type="revolute">
    <origin
      xyz="0.0075 -0.03897 0.036647"
      rpy="0 0 0" />
    <parent
      link="link3" />
    <child
      link="link9" />
    <axis
      xyz="-1 0 0" />
    <limit
      lower="-0.8"
      upper="0.8"
      effort="0"
      velocity="0" />
  </joint>
</robot>
