<?xml version="1.0" ?>
<robot name="wheeltec_robot">

    <link name="ugv_base_link">
        <visual>
            <origin xyz=" 0.08 0 0.04" rpy="0 0 0" />
            <geometry>
                <box size="0.23 0.11 0.05"/>
            </geometry>
            <material name="white">
                <color rgba="255 255 1 1"/>
            </material>
        </visual>
    </link>   

    <joint name="left_wheel_joint" type="continuous">
        <origin xyz="0 0.08 0.0325" rpy="1.57 0 0"/>
        <parent link="ugv_base_link"/>
        <child link="left_wheel_link"/>
        <axis xyz="0 1 0"/>
    </joint>

    <link name="left_wheel_link">
        <visual>
            <origin xyz="0 0 0" rpy="0 0 0" />
            <geometry>
                <cylinder radius="0.0325" length = "0.025"/>
            </geometry>
            <material name="black">
                <color rgba="0 0 0 1"/>
            </material>
        </visual>
    </link>

    <joint name="right_wheel_joint" type="continuous">
        <origin xyz="0 -0.08 0.0325" rpy="1.57 0 0"/>
        <parent link="ugv_base_link"/>
        <child link="right_wheel_link"/>
        <axis xyz="0 1 0"/>
    </joint>

    <link name="right_wheel_link">
        <visual>
            <origin xyz="0 0 0" rpy="0 0 0" />
            <geometry>
                <cylinder radius="0.0325" length = "0.025"/>
            </geometry>
            <material name="black">
                <color rgba="0 0 0 1"/>
            </material>
        </visual>
    </link>

      <joint name="left_front_joint" type="continuous">
        <origin xyz="0.14 0.08 0.0325" rpy="1.57 0 0"/>
        <parent link="ugv_base_link"/>
        <child link="left_front_link"/>
        <axis xyz="0 1 0"/>
    </joint>

    <link name="left_front_link">
        <visual>
            <origin xyz="0 0 0" rpy="0 0 0" />
            <geometry>
                <cylinder radius="0.0325" length = "0.025"/>
            </geometry>
            <material name="black">
                <color rgba="0 0 0 1"/>
            </material>
        </visual>
    </link>

    <joint name="right_front_joint" type="continuous">
        <origin xyz="0.14 -0.08 0.0325" rpy="1.57 0 0"/>
        <parent link="ugv_base_link"/>
        <child link="right_front_link"/>
        <axis xyz="0 1 0"/>
    </joint>

    <link name="right_front_link">
        <visual>
            <origin xyz="0 0 0" rpy="0 0 0" />
            <geometry>
                <cylinder radius="0.0325" length = "0.025"/>
            </geometry>
            <material name="black">
                <color rgba="0 0 0 1"/>
            </material>
        </visual>
    </link>


</robot>