<?xml version="1.0" ?>
<robot name="wheeltec_robot">

    <link name="base_link">
        <visual>
            <origin xyz=" 0.14 0 0.085" rpy="0 0 0" />
            <geometry>
                <box size="0.375 0.28 0.09"/>
            </geometry>
            <material name="white">
                <color rgba="1 1 1 1"/>
            </material>
        </visual>
    </link>   

    <joint name="left_wheel_joint" type="continuous">
        <origin xyz="0 0.165 0.05" rpy="1.57 0 0"/>
        <parent link="base_link"/>
        <child link="left_wheel_link"/>
        <axis xyz="0 1 0"/>
    </joint>

    <link name="left_wheel_link">
        <visual>
            <origin xyz="0 0 0" rpy="0 0 0" />
            <geometry>
                <cylinder radius="0.05" length = "0.04"/>
            </geometry>
            <material name="black">
                <color rgba="0 0 0 1"/>
            </material>
        </visual>
    </link>

    <joint name="right_wheel_joint" type="continuous">
        <origin xyz="0 -0.165 0.05" rpy="1.57 0 0"/>
        <parent link="base_link"/>
        <child link="right_wheel_link"/>
        <axis xyz="0 1 0"/>
    </joint>

    <link name="right_wheel_link">
        <visual>
            <origin xyz="0 0 0" rpy="0 0 0" />
            <geometry>
                <cylinder radius="0.05" length = "0.04"/>
            </geometry>
            <material name="black">
                <color rgba="0 0 0 1"/>
            </material>
        </visual>
    </link>

      <joint name="front_wheel_joint" type="continuous">
        <origin xyz="0.23 0 0.05" rpy="1.57 0 0"/>
        <parent link="base_link"/>
        <child link="front_wheel_link"/>
        <axis xyz="0 1 0"/>
    </joint>

    <link name="front_wheel_link">
        <visual>
            <origin xyz="0 0 0" rpy="0 0 0" />
            <geometry>
                <cylinder radius="0.05" length = "0.04"/>
            </geometry>
            <material name="black">
                <color rgba="0 0 0 1"/>
            </material>
        </visual>
    </link>



</robot>